Workbook
Name AddLoans: #REF!
Name Advertising: #REF!
Name Annual_Interest_Rate: #REF!
Name Beg_Bal: #REF!
Name Buildings: #REF!
Name Category1: '1 Produkt- und Absatzplanung '!$B$37
Name Category1: #REF!
Name Category1_Annual_Sales: '1 Produkt- und Absatzplanung '!$O$10
Name Category1_Annual_Sales: #REF!
Name Category1_SalesPrice: '1 Produkt- und Absatzplanung '!#REF!
Name Category1_SalesPrice: #REF!
Name Category2: '1 Produkt- und Absatzplanung '!$B$38
Name Category2: #REF!
Name Category2_Annual_Sales: '1 Produkt- und Absatzplanung '!$O$16
Name Category2_Annual_Sales: #REF!
Name Category2_SalesPrice: '1 Produkt- und Absatzplanung '!#REF!
Name Category2_SalesPrice: #REF!
Name Category3: '1 Produkt- und Absatzplanung '!$B$39
Name Category3: #REF!
Name Category3_Annual_Sales: '1 Produkt- und Absatzplanung '!$O$22
Name Category3_Annual_Sales: #REF!
Name Category3_SalesPrice: '1 Produkt- und Absatzplanung '!#REF!
Name Category3_SalesPrice: #REF!
Name Category4: '1 Produkt- und Absatzplanung '!#REF!
Name Category4: #REF!
Name Category4_Annual_Sales: '1 Produkt- und Absatzplanung '!#REF!
Name Category4_Annual_Sales: #REF!
Name Category4_SalesPrice: '1 Produkt- und Absatzplanung '!#REF!
Name Category4_SalesPrice: #REF!
Name Category5: '1 Produkt- und Absatzplanung '!#REF!
Name Category5: #REF!
Name Category5_Annual_Sales: '1 Produkt- und Absatzplanung '!#REF!
Name Category5_Annual_Sales: #REF!
Name Category5_SalesPrice: '1 Produkt- und Absatzplanung '!#REF!
Name Category5_SalesPrice: #REF!
Name Category6: '1 Produkt- und Absatzplanung '!#REF!
Name Category6: #REF!
Name Category6_Annual_Sales: '1 Produkt- und Absatzplanung '!#REF!
Name Category6_Annual_Sales: #REF!
Name Category6_SalesPrice: '1 Produkt- und Absatzplanung '!#REF!
Name Category6_SalesPrice: #REF!
Name Catergory6: '1 Produkt- und Absatzplanung '!#REF!
Name Catergory6: #REF!
Name CCDebt: #REF!
Name COGS_Annual_Total: '1 Produkt- und Absatzplanung '!$O$33
Name COGS_Annual_Total: #REF!
Name CommLoan: #REF!
Name CommMortgage: #REF!
Name ContingencyCash: #REF!
Name Equipment: #REF!
Name Extra_Pay: #REF!
Name Furniture: #REF!
Name Hours: '1 Produkt- und Absatzplanung '!#REF!
Name Info_Entered: #REF!
Name Int: #REF!
Name InterestRate_ShortTerm: #REF!
Name Inventory: #REF!
Name Land: #REF!
Name Last_Row: IF('1 Produkt- und Absatzplanung '!Values_Entered,Header_Row+'1 Produkt- und Absatzplanung '!Number_of_Payments,Header_Row)
Name Last_Row: IF(Values_Entered,Header_Row+Number_of_Payments,Header_Row)

Sheet Overview
C4: Übersicht | Q4: Bachelorseminar Businessplan
B5: 1 | C5: Produkt- und Absatzplanung | Q5: Judith Meder, M.Sc. | T5: meder@wiso.uni-koeln.de
B6: 2 | C6: Investitions- und Personalplanung | Q6: Professur für Entrepreneurship und Management
B7: 3 | C7: GuV - Cashflow | Q7: Prof. Dr. Christian Schwens
B8: 4 | C8: Break-Even
B9: 5 | C9: Liquiditätsplanung
B10: 6 | C10: Kapitalbedarfsplanung
B11: 7 | C11: Bilanz | J11: Click to navigate
B14: Nutzung der Finanzplan-Excel Diese Excel-Datei bietet ein vorgefertigtes Layout, an dessen grundsätzlichem Aufbau Sie sich orientieren sollten, um Ihren Finanzplan zu erstellen. Die Registerkarten sind teilweise mit Beispielpositionen und -werten gefüllt, um Ihnen ein Gefühl für die Struktur zu vermitteln. Diese Zahlen sind jedoch nur exemplarisch – Sie müssen die passenden Werte und Positionen für Ihre eigene Geschäftsidee selbst recherchieren und eintragen. Bitte erläutern Sie die Annahmen sowie die Berechnungsgrundlagen im Text. Hinweise: Produktions- und Absatzplanung: Diese Sektion ist für ein generisches Unternehmen konzipiert. Sie sollten hier Ihre eigene Berechnungsgrundlage für die Produkt- und Absatzplanung entwickeln, die zu Ihrem spezifischen Geschäftsmodell passt. Eine Verknüpfung zwischen dem Reiter Investitions- und Personalplanung und der Gewinn- und Verlustrechnung (GuV) ist bereits als Beispiel angelegt. Nutzen Sie dieses Beispiel als Vorlage, um eigene Verknüpfungen zwischen den verschiedenen Tabellenblättern zu erstellen.

Sheet 1 Produkt- und Absatzplanung 
B2: 1 - Produkt- und Absatzplanung
H3: Pilotphase J1
B4: Umsatzprognose | C4: Jan J1 | D4: Feb J1 | E4: Mär J1 | F4: Apr J1 | G4: Mai J1 | H4: Jun J1 | I4: Jul J1 | J4: Aug J1 | K4: Sep J1 | L4: Okt J1 | M4: Nov J1 | N4: Dez J1 | O4: Jahr 1 | P4: Q1 J2 | Q4: Q2 J2 | R4: Q3 J2 | S4: Q4 J2 | T4: Jahr 2 | U4: Q1 J3 | V4: Q2 J3 | W4: Q3 J3 | X4: Q4 J3 | Y4: Jahr 3 | Z4: Q1 J4 | AA4: Q2 J4 | AB4: Q3 J4 | AC4: Q4 J4 | AD4: Jahr 4
B5: Monatliche Wachstumsrate
B7: Produktlinien
B8: Starter | E8: Start Pilotprojekt
B9: Verkaufte Einheiten | C9: 0 | D9: 0 | E9: 6 | F9: 0 | G9: 0 | H9: 0 | I9: 0 | J9: 0 | K9: 0 | L9: 0 | M9: 0 | N9: 0 | O9: 0 | P9: 2 | Q9: 1 | R9: 3 | S9: 2 | T9: =SUM(P9:S9) -> 8 | U9: 3 | V9: 2 | W9: 4 | X9: 3 | Y9: =SUM(U9:X9) -> 12 | Z9: 1 | AA9: 1 | AB9: 5 | AC9: 3 | AD9: =SUM(Z9:AC9)-2 -> 8
B10: Gesamtumsatz | C10: 0 | D10: 0 | E10: 0 | F10: 0 | G10: 0 | H10: 0 | I10: 0 | J10: 0 | K10: 0 | L10: 0 | M10: 0 | N10: 0 | O10: =SUM(C10:N10) -> 0 | P10: =$C$37*P9 -> 8400 | Q10: =$C$37*Q9 -> 4200 | R10: =$C$37*R9 -> 12600 | S10: =$C$37*S9 -> 8400 | T10: =SUM(P10:S10) -> 33600 | U10: =$C$37*U9 -> 12600 | V10: =$C$37*V9 -> 8400 | W10: =$C$37*W9 -> 16800 | X10: =$C$37*X9 -> 12600 | Y10: =SUM(U10:X10) -> 50400 | Z10: =$C$37*Z9 -> 4200 | AA10: =$C$37*AA9 -> 4200 | AB10: =$C$37*AB9 -> 21000 | AC10: =$C$37*AC9 -> 12600 | AD10: =SUM(Z10:AC10) -> 42000
B11: Gesamte COGS | C11: 0 | D11: 0 | E11: 0 | F11: 0 | G11: 0 | H11: 0 | I11: 0 | J11: 0 | K11: 0 | L11: 0 | M11: 0 | N11: 0 | O11: =SUM(C11:N11) -> 0 | T11: =SUM(P11:S11) -> 0 | Y11: =SUM(U11:X11) -> 0 | AD11: =SUM(Z11:AC11) -> 0
B12: Gesamtmarge | C12: 0 | D12: 0 | E12: 0 | F12: 0 | G12: 0 | H12: 0 | I12: 0 | J12: 0 | K12: 0 | L12: 0 | M12: 0 | N12: 0 | O12: =SUM(C12:N12) -> 0 | P12: =P10-P11 -> 8400 | Q12: =Q10-Q11 -> 4200 | R12: =R10-R11 -> 12600 | S12: =S10-S11 -> 8400 | T12: =SUM(P12:S12) -> 33600 | U12: =U10-U11 -> 12600 | V12: =V10-V11 -> 8400 | W12: =W10-W11 -> 16800 | X12: =X10-X11 -> 12600 | Y12: =SUM(U12:X12) -> 50400 | Z12: =Z10-Z11 -> 4200 | AA12: =AA10-AA11 -> 4200 | AB12: =AB10-AB11 -> 21000 | AC12: =AC10-AC11 -> 12600 | AD12: =SUM(Z12:AC12) -> 42000
B14: Pro
B15: Verkaufte Einheiten | C15: 0 | D15: 0 | E15: 0 | F15: 0 | G15: 0 | H15: 0 | I15: 0 | J15: 0 | K15: 0 | L15: 0 | M15: 0 | N15: 0 | O15: 3 | P15: 5 | Q15: 2 | R15: 4 | S15: 3 | T15: =SUM(P15:S15) -> 14 | U15: 4 | V15: 5 | W15: 8 | X15: 7 | Y15: =SUM(U15:X15) -> 24 | Z15: 2 | AA15: 1 | AB15: 9 | AC15: 6 | AD15: =SUM(Z15:AC15)-3 -> 15 | AG15: Im deutschen Ligasystem spielen 31.645 Mannschaften in 2.235 Ligen. Davon ist eure Zielgruppe: Beglaubigt
B16: Gesamtumsatz | C16: 0 | D16: 0 | E16: 0 | F16: 0 | G16: 0 | H16: 0 | I16: =$C$38*I15 -> 0 | J16: 0 | K16: 0 | L16: =$C$38*L15 -> 0 | M16: 0 | N16: =$C$38*N15 -> 0 | O16: =SUM(C16:N16) -> 0 | P16: =$C$38*P15 -> 29500 | Q16: =$C$38*Q15 -> 11800 | R16: =$C$38*R15 -> 23600 | S16: =$C$38*S15 -> 17700 | T16: =SUM(P16:S16) -> 82600 | U16: =$C$38*U15 -> 23600 | V16: =$C$38*V15 -> 29500 | W16: =$C$38*W15 -> 47200 | X16: =$C$38*X15 -> 41300 | Y16: =SUM(U16:X16) -> 141600 | Z16: =$C$38*Z15 -> 11800 | AA16: =$C$38*AA15 -> 5900 | AB16: =$C$38*AB15 -> 53100 | AC16: =$C$38*AC15 -> 35400 | AD16: =SUM(Z16:AC16) -> 106200
B17: Gesamte COGS | C17: =$D$38*C15 -> 0 | D17: =$D$38*D15 -> 0 | E17: =$D$38*E15 -> 0 | F17: =$D$38*F15 -> 0 | G17: =$D$38*G15 -> 0 | H17: =$D$38*H15 -> 0 | I17: =$D$38*I15 -> 0 | J17: =$D$38*J15 -> 0 | ... N17: =$D$38*N15 -> 0 | O17: =SUM(C17:N17) -> 0 | T17: =SUM(P17:S17) -> 0 | Y17: =SUM(U17:X17) -> 0 | AD17: =SUM(Z17:AC17) -> 0 | AG17: Liga | AH17: Männer | AI17: Frauen | AJ17: Gesamt
B18: Gesamtmarge | C18: 0 | D18: 0 | E18: =E16-E17 -> 0 | F18: =F16-F17 -> 0 | G18: =G16-G17 -> 0 | H18: =H16-H17 -> 0 | I18: 0 | J18: =J16-J17 -> 0 | K18: =K16-K17 -> 0 | L18: 0 | M18: =M16-M17 -> 0 | N18: 0 | O18: =SUM(C18:N18) -> 0 | P18: =P16-P17 -> 29500 | Q18: =Q16-Q17 -> 11800 | R18: =R16-R17 -> 23600 | S18: =S16-S17 -> 17700 | T18: =SUM(P18:S18) -> 82600 | U18: =U16-U17 -> 23600 | V18: =V16-V17 -> 29500 | W18: =W16-W17 -> 47200 | X18: =X16-X17 -> 41300 | Y18: =SUM(U18:X18) -> 141600 | Z18: =Z16-Z17 -> 11800 | AA18: =AA16-AA17 -> 5900 | AB18: =AB16-AB17 -> 53100 | AC18: =AC16-AC17 -> 35400 | AD18: =SUM(Z18:AC18) -> 106200 | AG18: Regionalliga (5 Staffeln à 18) | AH18: 90 | AI18: 72 | AJ18: 162
AG19: Oberliga (12 Staffeln à 16) | AH19: 192 | AI19: 160 | AJ19: 352
B20: Elite | AG20: Verbandsliga/Landesliga | AH20: ~800 | AI20: ~400 | AJ20: ~1.200
B21: Verkaufte Einheiten | C21: 0 | D21: 0 | E21: 0 | F21: 0 | G21: 0 | H21: 0 | I21: 0 | J21: 0 | K21: 0 | L21: 0 | M21: 0 | N21: 0 | O21: 1 | P21: 1 | Q21: 1 | R21: 3 | S21: 2 | T21: =SUM(P21:S21) -> 7 | U21: 1 | V21: 1 | W21: 3 | X21: 2 | Y21: =SUM(U21:X21) -> 7 | Z21: 1 | AA21: 2 | AB21: 4 | AC21: 1 | AD21: =SUM(Z21:AC21)-2 -> 6 | AG21: Österreich + Schweiz (+20%) | AJ21: ~340
B22: Gesamtumsatz | C22: 0 | D22: 0 | E22: =$C$39*E21 -> 0 | F22: =$C$39*F21 -> 0 | G22: =$C$39*G21 -> 0 | H22: =$C$39*H21 -> 0 | I22: 0 | J22: =$C$39*J21 -> 0 | K22: 0 | L22: =$C$39*L21 -> 0 | M22: =$C$39*M21 -> 0 | N22: =$C$39*N21 -> 0 | O22: =SUM(C22:N22) -> 0 | P22: =$C$39*P21 -> 8200 | Q22: =$C$39*Q21 -> 8200 | R22: =$C$39*R21 -> 24600 | S22: =$C$39*S21 -> 16400 | T22: =SUM(P22:S22) -> 57400 | U22: =$C$39*U21 -> 8200 | V22: =$C$39*V21 -> 8200 | W22: =$C$39*W21 -> 24600 | X22: =$C$39*X21 -> 16400 | Y22: =SUM(U22:X22) -> 57400 | Z22: =$C$39*Z21 -> 8200 | AA22: =$C$39*AA21 -> 16400 | AB22: =$C$39*AB21 -> 32800 | AC22: =$C$39*AC21 -> 8200 | AD22: =SUM(Z22:AC22) -> 65600 | AG22: TAM gesamt | AJ22: ~2.054
B23: Gesamte COGS | C23: =$D$39*C21 -> 0 | D23: =$D$39*D21 -> 0 | E23: =$D$39*E21 -> 0 | F23: =$D$39*F21 -> 0 | G23: =$D$39*G21 -> 0 | H23: =$D$39*H21 -> 0 | I23: =$D$39*I21 -> 0 | J23: =$D$39*J21 -> 0 | ... N23: =$D$39*N21 -> 0 | O23: =SUM(C23:N23) -> 0 | T23: =SUM(P23:S23) -> 0 | Y23: =SUM(U23:X23) -> 0 | AD23: =SUM(Z23:AC23) -> 0
B24: Gesamtmarge | C24: 0 | D24: 0 | E24: 0 | F24: 0 | G24: 0 | H24: 0 | I24: =I22-I23 -> 0 | J24: 0 | K24: =K22-K23 -> 0 | L24: 0 | M24: 0 | N24: 0 | O24: =SUM(C24:N24) -> 0 | P24: =P22-P23 -> 8200 | Q24: =Q22-Q23 -> 8200 | R24: =R22-R23 -> 24600 | S24: =S22-S23 -> 16400 | T24: =SUM(P24:S24) -> 57400 | U24: =U22-U23 -> 8200 | V24: =V22-V23 -> 8200 | W24: =W22-W23 -> 24600 | X24: =X22-X23 -> 16400 | Y24: =SUM(U24:X24) -> 57400 | Z24: =Z22-Z23 -> 8200 | AA24: =AA22-AA23 -> 16400 | AB24: =AB22-AB23 -> 32800 | AC24: =AC22-AC23 -> 8200 | AD24: =SUM(Z24:AC24) -> 65600
AG25: Euer realistischer Zielmarkt (SAM):
B26: Subscription
B27: Aktive Vereine | C27: 0 | D27: 0 | E27: =E9+E15+E21 -> 6 | F27: =E27+(F9+F15+F21) -> 6 | G27: =F27+(G9+G15+G21) -> 6 | H27: =G27+(H9+H15+H21) -> 6 | I27: =H27+(I9+I15+I21) -> 6 | J27: =I27+(J9+J15+J21) -> 6 | K27: =J27+(K9+K15+K21) -> 6 | L27: =K27+(L9+L15+L21) -> 6 | M27: =L27+(M9+M15+M21) -> 6 | N27: =M27+(N9+N15+N21) -> 6 | O27: =O9+O15+O21 -> 4 | P27: =P9+P15+P21 -> 8 | Q27: =Q9+Q15+Q21 -> 4 | R27: =R9+R15+R21 -> 10 | S27: =S9+S15+S21 -> 7 | T27: =T9+T15+T21+O27 -> 33 | U27: =U9+U15+U21 -> 8 | V27: =V9+V15+V21 -> 8 | W27: =W9+W15+W21 -> 15 | X27: =X9+X15+X21 -> 12 | Y27: =(Y9+Y15+Y21+T27) -> 76 | Z27: =Z9+Z15+Z21 -> 4 | AA27: =AA9+AA15+AA21 -> 4 | AB27: =AB9+AB15+AB21 -> 18 | AC27: =AC9+AC15+AC21 -> 10 | AD27: =AD9+AD15+AD21+Y27 -> 105 | AG27: Nur ambitionierte Vereine mit Budget — erfahrungsgemäß obere 25% der Amateurligen:
B28: Gesamtumsatz | C28: 0 | D28: 0 | F28: =F9*$C$42+F15*$C$43+F21*$C$44+E28 -> 0 | G28: =G9*$C$42+G15*$C$43+G21*$C$44+F28 -> 0 | H28: =H9*$C$42+H15*$C$43+H21*$C$44+G28 -> 0 | I28: =I9*$C$42+I15*$C$43+I21*$C$44+H28 -> 0 | J28: =J9*$C$42+J15*$C$43+J21*$C$44+I28 -> 0 | K28: =K9*$C$42+K15*$C$43+K21*$C$44+J28 -> 0 | L28: =L9*$C$42+L15*$C$43+L21*$C$44+K28 -> 0 | M28: =M9*$C$42+M15*$C$43+M21*$C$44+L28 -> 0 | N28: =N9*$C$42+N15*$C$43+N21*$C$44+M28 -> 0 | O28: =SUM(C28:N28) -> 0 | P28: =P9*$C$42+P15*$C$43+P21*$C$44+O28 -> 2642 | Q28: =Q9*$C$42+Q15*$C$43+Q21*$C$44+P28 -> 4018 | R28: =R9*$C$42+R15*$C$43+R21*$C$44+Q28 -> 7448 | S28: =S9*$C$42+S15*$C$43+S21*$C$44+R28 -> 9851 | T28: =SUM(P28:S28) -> 23959 | U28: =U9*$C$42+U15*$C$43+U21*$C$44+T28 -> 26471 | V28: =V9*$C$42+V15*$C$43+V21*$C$44+U28 -> 29113 | W28: =W9*$C$42+W15*$C$43+W21*$C$44+V28 -> 34158 | X28: =X9*$C$42+X15*$C$43+X21*$C$44+W28 -> 38176 | Y28: =SUM(U28:X28) -> 127918 | Z28: =Z9*$C$42+Z15*$C$43+Z21*$C$44+Y28 -> 129294 | AA28: =AA9*$C$42+AA15*$C$43+AA21*$C$44+Z28 -> 130780 | AB28: =AB9*$C$42+AB15*$C$43+AB21*$C$44+AA28 -> 136852 | AC28: =AC9*$C$42+AC15*$C$43+AC21*$C$44+AB28 -> 140062 | AD28: =SUM(Z28:AC28) -> 536988
B29: Gesamte COGS | C29: 0 | D29: 0 | E29: =E27*$C$82 -> 102 | F29: =F27*$C$82 -> 102 | G29: =G27*$C$82 -> 102 | H29: =H27*$C$82 -> 102 | I29: =I27*$C$82 -> 102 | J29: =J27*$C$82 -> 102 | K29: =K27*$C$82 -> 102 | L29: =L27*$C$82 -> 102 | ... N29: =N27*$C$82 -> 102 | O29: =SUM(C29:N29) -> 1020 | P29: =(P27*$C$82)*3 -> 408 | Q29: =(Q27*$C$82)*3+P$29 -> 612 | R29: =(R27*$C$82)*3+Q$29 -> 1122 | S29: =(S27*$C$82)*3+R$29 -> 1479 | T29: =SUM(P29:S29) -> 3621 | U29: =(U27*$C$82)*3+T$29 -> 4029 | V29: =(V27*$C$82)*3+U$29 -> 4437 | W29: =(W27*$C$82)*3+V$29 -> 5202 | X29: =(X27*$C$82)*3+W$29 -> 5814 | Y29: =SUM(U29:X29) -> 19482 | Z29: =(Z27*$C$82)*3+Y$29 -> 19686 | AA29: =(AA27*$C$82)*3+Z$29 -> 19890 | AB29: =(AB27*$C$82)*3+AA$29 -> 20808 | AC29: =(AC27*$C$82)*3+AB$29 -> 21318 | AD29: =SUM(Z29:AC29) -> 81702 | AG29: SAM = ~500 Vereine im DACH-Raum
B30: Gesamtmarge | C30: 0 | D30: 0 | E30: =E28-E29 -> -102 | F30: =F28-F29 -> -102 | G30: =G28-G29 -> -102 | H30: =H28-H29 -> -102 | I30: =I28-I29 -> -102 | J30: =J28-J29 -> -102 | K30: =K28-K29 -> -102 | L30: =L28-L29 -> -102 | ... N30: =N28-N29 -> -102 | O30: =SUM(C30:N30) -> -1020 | P30: =P28-P29 -> 2234 | Q30: =Q28-Q29 -> 3406 | R30: =R28-R29 -> 6326 | S30: =S28-S29 -> 8372 | T30: =SUM(P30:S30) -> 20338 | U30: =U28-U29 -> 22442 | V30: =V28-V29 -> 24676 | W30: =W28-W29 -> 28956 | X30: =X28-X29 -> 32362 | Y30: =SUM(U30:X30) -> 108436 | Z30: =Z28-Z29 -> 109608 | AA30: =AA28-AA29 -> 110890 | AB30: =AB28-AB29 -> 116044 | AC30: =AC28-AC29 -> 118744 | AD30: =SUM(Z30:AC30) -> 455286
B31: Gesamtzahl verkaufte Einheiten
B32: Gesamtumsatz | C32: =C22+C16+C10+C28 -> 0 | D32: =D22+D16+D10+D28 -> 0 | E32: =E22+E16+E10+E28 -> 0 | F32: =F22+F16+F10+F28 -> 0 | G32: =G22+G16+G10+G28 -> 0 | H32: =H22+H16+H10+H28 -> 0 | I32: =I22+I16+I10+I28 -> 0 | J32: =J22+J16+J10+J28 -> 0 | ... N32: =N22+N16+N10+N28 -> 0 | O32: =SUM(C32:N32) -> 0 | P32: =P22+P16+P10+P28 -> 48742 | Q32: =Q22+Q16+Q10+Q28 -> 28218 | R32: =R22+R16+R10+R28 -> 68248 | S32: =S22+S16+S10+S28 -> 52351 | T32: =SUM(P32:S32) -> 197559 | U32: =U22+U16+U10+U28 -> 70871 | V32: =V22+V16+V10+V28 -> 75213 | W32: =W22+W16+W10+W28 -> 122758 | X32: =X22+X16+X10+X28 -> 108476 | Y32: =SUM(U32:X32) -> 377318 | Z32: =Z22+Z16+Z10+Z28 -> 153494 | AA32: =AA22+AA16+AA10+AA28 -> 157280 | AB32: =AB22+AB16+AB10+AB28 -> 243752 | AC32: =AC22+AC16+AC10+AC28 -> 196262 | AD32: =SUM(Z32:AC32) -> 750788
B33: Gesamte COGS | C33: =C23+C17+C11+C29 -> 0 | D33: =D23+D17+D11+D29 -> 0 | E33: =E23+E17+E11+E29 -> 102 | F33: =F23+F17+F11+F29 -> 102 | G33: =G23+G17+G11+G29 -> 102 | H33: =H23+H17+H11+H29 -> 102 | I33: =I23+I17+I11+I29 -> 102 | J33: =J23+J17+J11+J29 -> 102 | ... N33: =N23+N17+N11+N29 -> 102 | O33: =SUM(C33:N33) -> 1020 | P33: =P23+P17+P11+P29 -> 408 | Q33: =Q23+Q17+Q11+Q29 -> 612 | R33: =R23+R17+R11+R29 -> 1122 | S33: =S23+S17+S11+S29 -> 1479 | T33: =SUM(P33:S33) -> 3621 | U33: =U23+U17+U11+U29 -> 4029 | V33: =V23+V17+V11+V29 -> 4437 | W33: =W23+W17+W11+W29 -> 5202 | X33: =X23+X17+X11+X29 -> 5814 | Y33: =SUM(U33:X33) -> 19482 | Z33: =Z23+Z17+Z11+Z29 -> 19686 | AA33: =AA23+AA17+AA11+AA29 -> 19890 | AB33: =AB23+AB17+AB11+AB29 -> 20808 | AC33: =AC23+AC17+AC11+AC29 -> 21318 | AD33: =SUM(Z33:AC33) -> 81702 | AG33: Euer SOM nach 4 Jahren:
B34: Gesamte Marge | C34: =C24+C18+C12+C30 -> 0 | D34: =D24+D18+D12+D30 -> 0 | E34: =E24+E18+E12+E30 -> -102 | F34: =F24+F18+F12+F30 -> -102 | G34: =G24+G18+G12+G30 -> -102 | H34: =H24+H18+H12+H30 -> -102 | I34: =I24+I18+I12+I30 -> -102 | J34: =J24+J18+J12+J30 -> -102 | ... N34: =N24+N18+N12+N30 -> -102 | O34: =SUM(C34:N34) -> -1020 | P34: =P24+P18+P12+P30 -> 48334 | Q34: =Q24+Q18+Q12+Q30 -> 27606 | R34: =R24+R18+R12+R30 -> 67126 | S34: =S24+S18+S12+S30 -> 50872 | T34: =SUM(P34:S34) -> 193938 | U34: =U24+U18+U12+U30 -> 66842 | V34: =V24+V18+V12+V30 -> 70776 | W34: =W24+W18+W12+W30 -> 117556 | X34: =X24+X18+X12+X30 -> 102662 | Y34: =SUM(U34:X34) -> 357836 | Z34: =Z24+Z18+Z12+Z30 -> 133808 | AA34: =AA24+AA18+AA12+AA30 -> 137390 | AB34: =AB24+AB18+AB12+AB30 -> 222944 | AC34: =AC24+AC18+AC12+AC30 -> 174944 | AD34: =SUM(Z34:AC34) -> 669086
AG35: 110 Vereine von 500 = 22% Marktdurchdringung
B36: Produktlinien | C36: Sales Price Per Unit | D36: EK | E36: Margin Per Unit | AC36: check: | AD36: =(AD32-AD33)=AD34 -> TRUE
B37: Starter | C37: 4200 | D37: =D70 -> 3390 | E37: =C37-D37 -> 810 | AG37: Das ist mit Rogers Diffusion Curve (2003) perfekt begründbar — Early Adopters + Early Majority = 34% in den ersten 4 Jahren. 22% ist konservativ und glaubwürdig.
B38: Pro | C38: 5900 | D38: =E70 -> 4745 | E38: =C38-D38 -> 1155
B39: Elite | C39: 8200 | D39: =F70 -> 6595 | E39: =C39-D39 -> 1605
B41: Produktlinien | C41: Subscription(monatlich) | D41: COGS Per Unit | E41: Margin Per Unit
B42: Starter | C42: 219 | D42: 17 | E42: =C42-D42 -> 202
B43: Pro | C43: 349 | D43: 17 | E43: =C43-D43 -> 332
B44: Elite | C44: 459 | D44: 17 | E44: =C44-D44 -> 442
...

Sheet 2 Investit- und Personalplanung
B2: 2 - Investitions- und Personalplanung
B4: Startaufwendungen | F4: Personalplanung
B5: Schritte zur Unternehmensgründung | F5: Planungszeitraum | G5: Jahr 1 | I5: Jahr 2 | K5: Jahr 3 | M5: Jahr 4 | O5: Lohn-
B6: Gewerbeanmeldung | C6: 33 | G6: Anzahl | H6: Personal- | I6: Anzahl | J6: Personal- | K6: Anzahl | L6: Personal- | M6: Anzahl | N6: Personal- | O6: nebenkosten
B7: Bankkonto | G7: Mitarbeiter | H7: kosten | I7: Mitarbeiter | J7: kosten | K7: Mitarbeiter | L7: kosten | M7: Mitarbeiter | N7: kosten
B8: Finanzamt informieren | F8: Management
B9: Berufsverband informieren | F9: Geschäftsführer (CEO) | G9: 1 | H9: 0 | I9: 1 | J9: 24000 | K9: 1 | L9: 30000 | M9: 1 | N9: 36000 | O9: 0.21
B10: Eintragung Handelsregister | C10: 150 | F10: Finanzvorstand (CFO) | G10: 1 | H10: 0 | I10: 1 | J10: 24000 | K10: 1 | L10: 30000 | M10: 1 | N10: 36000 | O10: 0.21
B11: IHK/ HWK | C11: 150 | F11: Technikvorstand (CTO) | G11: 1 | H11: 0 | I11: 1 | J11: 24000 | K11: 1 | L11: 30000 | M11: 1 | N11: 36000 | O11: 0.21
B12: Notar + Gesellschaftsvertrag | C12: 1500 | F12: Marketing (CMO) | G12: 1 | H12: 0 | I12: 1 | J12: 24000 | K12: 1 | L12: 30000 | M12: 1 | N12: 36000 | O12: 0.21
F13: Betriebsleiter (COO) | G13: 1 | H13: 0 | I13: 1 | J13: 24000 | K13: 1 | L13: 30000 | M13: 1 | N13: 36000 | O13: 0.21
B14: Gesamtkosten für die Unternehmensgründung | C14: =SUM(C6:C12) -> 1833 | F14: Gesamt | H14: {=SUM(G9:G13*H9:H13*(1+O9:O13))} -> 0 | J14: {=SUM(I9:I13*J9:J13*(1+O9:O13))} -> 145200 | L14: {=SUM(K9:K13*L9:L13*(1+O9:O13))} -> 181500 | N14: {=SUM(M9:M13*N9:N13*(1+O9:O13))} -> 217800
B15: IT-Schritte | F15: Forschung & Entwicklung
B16: Website-Entwicklung | F16: Ingenieure | O16: 0.21
B17: App-Entwicklung Frontend | F17: Techniker | O17: 0.21
B18: App-Entwicklung Backend | C18: 25000 | F18: Assistenten | O18: 0.21
B19: IT-Ausstattung | C19: 5000 | F19: Gesamt | H19: {=SUM(G16:G18*H16:H18*(1+O16:O18))} -> 0 | J19: {=SUM(I15:I18*J15:J18*(1+O15:O18))} -> 0 | L19: {=SUM(K15:K18*L15:L18*(1+O15:O18))} -> 0 | N19: {=SUM(M14:M18*N14:N18*(1+O14:O18))} -> 0
B20: Weitere Position | F20: Produktion & Herstellung
B21: Gesamte IT-Kosten | C21: =SUM(C16:C20) -> 30000 | F21: Beschaffung | O21: 0.21
B22: Regulatorische Registrierungen | F22: Fertigung | O22: 0.21
B23: Patent | F23: Logistik | O23: 0.21
B24: Markenregistrierung | C24: 290 | F24: Gesamt | H24: {=SUM(G21:G23*H21:H23*(1+O21:O23))} -> 0 | J24: {=SUM(I20:I23*J20:J23*(1+O20:O23))} -> 0 | L24: {=SUM(K20:K23*L20:L23*(1+O20:O23))} -> 0 | N24: {=SUM(M19:M23*N19:N23*(1+O19:O23))} -> 0
B25: Gesamte produktbezogene Kosten | C25: =SUM(C23:C24) -> 290 | F25: Marketing & Vertrieb
F26: Marketing | O26: 0.21
B27: Gesamtkosten: | C27: =SUM(C25,C14,C21) -> 32123 | F27: Vertrieb (CEO) | O27: 0.21
F28: Service | O28: 0.21
B29: Laufende Kosten | F29: Gesamt | H29: {=SUM(G26:G28*H26:H28*(1+O26:O28))} -> 0 | J29: {=SUM(I25:I28*J25:J28*(1+O25:O28))} -> 0 | L29: {=SUM(K25:K28*L25:L28*(1+O25:O28))} -> 0 | N29: {=SUM(M24:M28*N24:N28*(1+O24:O28))} -> 0
B30: Büro und Verwaltung | F30: Verwaltung
B31: Miete oder Leasing | C31: 0 | F31: Buchhaltung | O31: 0.21
B32: Nebenkosten (Strom, Wasser, Heizung) | C32: 0 | F32: Personal | O32: 0.21
B33: Gesamte Büro- und Verwaltungskosten | C33: =SUM(C31:C32) -> 0 | F33: Sekretariat | O33: 0.21
B34: Technologie und Infrastruktur | F34: Gesamt | H34: {=SUM(G31:G33*H31:H33*(1+O31:O33))} -> 0 | J34: {=SUM(I30:I33*J30:J33*(1+O30:O33))} -> 0 | L34: {=SUM(K30:K33*L30:L33*(1+O30:O33))} -> 0 | N34: {=SUM(M29:M33*N29:N33*(1+O29:O33))} -> 0
B35: Internetdienste | C35: 0 | F35: Auszubildende und Praktikanten
B36: Cloud-Infrastruktur | C36: =8*'1 Produkt- und Absatzplanung '!E9 -> 48 | F36: Werkstudent | K36: 1 | L36: 14400 | M36: 1 | N36: 16640 | O36: 0.21
B37: Software & Collaboration Tools (GitHub, Figma, Notion, Google Workspace) | C37: 52 | F37: Gesamt | H37: {=SUM(G36:G37*H36:H37*(1+O36:O37))} -> 0 | J37: {=SUM(I35:I36*J35:J36*(1+O35:O36))} -> 0 | L37: {=SUM(K35:K36*L35:L36*(1+O35:O36))} -> 17424 | N37: {=SUM(M35:M36*N35:N36*(1+O35:O36))} -> 20134.4
B38: Website-Hosting und Software | C38: 50
B39: Gesamte Technologie- und Infrastrukturkosten | C39: =SUM(C35:C38) -> 150 | F39: Gesamte Personalkosten: | H39: =H14+H19+H24+H29+H34+H37 -> 0 | J39: =J14+J19+J24+J29+J34+J37 -> 145200 | L39: =L14+L19+L24+L29+L34+L37 -> 198924 | N39: =N14+N19+N24+N29+N34+N37 -> 237934.4
B41: Gesamtkosten: | C41: =C27+C39 -> 32273
B44: Wasserman (2012): Gründer die in der Frühphase auf Vergütung verzichten signalisieren "Skin in the Game" gegenüber Investoren und Banken – das stärkt die Kreditwürdigkeit erheblich.
B45: Sweat Equity begründen (Hellmann & Puri, 2002): Technische Gründer ersetzen externe Entwicklungskosten durch Eigenleistung, was den Kapitalbedarf in der Seed-Phase signifikant senkt.
...

Sheet 3 GuV - Cashflow
B2: 3 - Gewinn- und Verlustrechnung
C4: Jan J1 | D4: Feb J1 | E4: Mär J1 | F4: Apr J1 | G4: Mai J1 | H4: Jun J1 | I4: Jul J1 | J4: Aug J1 | K4: Sep J1 | L4: Okt J1 | M4: Nov J1 | N4: Dez J1 | O4: Jahr 1 | P4: Q1 J2 | Q4: Q2 J2 | R4: Q3 J2 | S4: Q4 J2 | T4: Jahr 2 | U4: Q1 J3 | V4: Q2 J3 | W4: Q3 J3 | X4: Q4 J3 | Y4: Jahr 3 | Z4: Q1 J4 | AA4: Q2 J4 | AB4: Q3 J4 | AC4: Q4 J4 | AD4: Jahr 4
B5: Erträge
B6: Umsatzerlöse | C6: 0 | D6: 0 | E6: 0 | F6: 0 | G6: 0 | H6: 0 | I6: 0 | J6: 0 | K6: 0 | L6: 0 | M6: 0 | N6: 0 | O6: =SUM(C6:N6) -> 0 | P6: ='1 Produkt- und Absatzplanung '!P32 -> 48742 | Q6: ='1 Produkt- und Absatzplanung '!Q32 -> 28218 | R6: ='1 Produkt- und Absatzplanung '!R32 -> 68248 | S6: ='1 Produkt- und Absatzplanung '!S32 -> 52351 | T6: =SUM(P6:S6) -> 197559 | U6: ='1 Produkt- und Absatzplanung '!U32 -> 70871 | V6: ='1 Produkt- und Absatzplanung '!V32 -> 75213 | W6: ='1 Produkt- und Absatzplanung '!W32 -> 122758 | X6: ='1 Produkt- und Absatzplanung '!X32 -> 108476 | Y6: =SUM(U6:X6) -> 377318 | Z6: ='1 Produkt- und Absatzplanung '!Z32 -> 153494 | AA6: ='1 Produkt- und Absatzplanung '!AA32 -> 157280 | AB6: ='1 Produkt- und Absatzplanung '!AB32 -> 243752 | AC6: ='1 Produkt- und Absatzplanung '!AC32 -> 196262 | AD6: =SUM(Z6:AC6) -> 750788
B7: Sonstige Erträge | C7: 0 | D7: 0 | E7: 0 | F7: 0 | G7: 0 | H7: 0 | I7: 0 | J7: 0 | K7: 0 | L7: 0 | M7: 0 | N7: 0 | O7: =SUM(C7:N7) -> 0 | T7: =SUM(P7:S7) -> 0 | Y7: =SUM(U7:X7) -> 0 | AD7: =SUM(Z7:AC7) -> 0
B8: Weitere Position | O8: =SUM(C8:N8) -> 0 | T8: =SUM(P8:S8) -> 0 | Y8: =SUM(U8:X8) -> 0 | AD8: =SUM(Z8:AC8) -> 0
B9: Weitere Position | O9: =SUM(C9:N9) -> 0 | T9: =SUM(P9:S9) -> 0 | Y9: =SUM(U9:X9) -> 0 | AD9: =SUM(Z9:AC9) -> 0
B10: Weitere Position | O10: =SUM(C10:N10) -> 0 | T10: =SUM(P10:S10) -> 0 | Y10: =SUM(U10:X10) -> 0 | AD10: =SUM(Z10:AC10) -> 0
B11: Summe Erträge | C11: =SUM(C6:C10) -> 0 | D11: =SUM(D6:D10) -> 0 | E11: =SUM(E6:E10) -> 0 | F11: =SUM(F6:F10) -> 0 | G11: =SUM(G6:G10) -> 0 | H11: =SUM(H6:H10) -> 0 | I11: =SUM(I6:I10) -> 0 | J11: =SUM(J6:J10) -> 0 | ... AD11: =SUM(AD6:AD10) -> 750788
B13: Aufwendungen
B14: Personalkosten | C14: ='2 Investit- und Personalplanung'!$H$39/12 -> 0 | D14: ='2 Investit- und Personalplanung'!$H$39/12 -> 0 | E14: ='2 Investit- und Personalplanung'!$H$39/12 -> 0 | F14: ='2 Investit- und Personalplanung'!$H$39/12 -> 0 | G14: ='2 Investit- und Personalplanung'!$H$39/12 -> 0 | H14: ='2 Investit- und Personalplanung'!$H$39/12 -> 0 | I14: ='2 Investit- und Personalplanung'!$H$39/12 -> 0 | J14: ='2 Investit- und Personalplanung'!$H$39/12 -> 0 | ... N14: ='2 Investit- und Personalplanung'!$H$39/12 -> 0 | O14: =SUM(C14:N14) -> 0 | P14: ='2 Investit- und Personalplanung'!$J$39/4 -> 36300 | Q14: ='2 Investit- und Personalplanung'!$J$39/4 -> 36300 | R14: ='2 Investit- und Personalplanung'!$J$39/4 -> 36300 | S14: ='2 Investit- und Personalplanung'!$J$39/4 -> 36300 | T14: =SUM(P14:S14) -> 145200 | U14: ='2 Investit- und Personalplanung'!$L$39/4 -> 49731 | V14: ='2 Investit- und Personalplanung'!$L$39/4 -> 49731 | W14: ='2 Investit- und Personalplanung'!$L$39/4 -> 49731 | X14: ='2 Investit- und Personalplanung'!$L$39/4 -> 49731 | Y14: =SUM(U14:X14) -> 198924 | Z14: ='2 Investit- und Personalplanung'!$N$39/4 -> 59483.6 | AA14: ='2 Investit- und Personalplanung'!$N$39/4 -> 59483.6 | AB14: ='2 Investit- und Personalplanung'!$N$39/4 -> 59483.6 | AC14: ='2 Investit- und Personalplanung'!$N$39/4 -> 59483.6 | AD14: =SUM(Z14:AC14) -> 237934.4
B15: Kosten der verkauften Waren (COGS) | C15: 0 | D15: 0 | E15: ='1 Produkt- und Absatzplanung '!E33 -> 102 | F15: ='1 Produkt- und Absatzplanung '!F33 -> 102 | G15: ='1 Produkt- und Absatzplanung '!G33 -> 102 | H15: ='1 Produkt- und Absatzplanung '!H33 -> 102 | I15: ='1 Produkt- und Absatzplanung '!I33 -> 102 | J15: ='1 Produkt- und Absatzplanung '!J33 -> 102 | K15: ='1 Produkt- und Absatzplanung '!K33 -> 102 | L15: ='1 Produkt- und Absatzplanung '!L33 -> 102 | ... N15: ='1 Produkt- und Absatzplanung '!N33 -> 102 | O15: =SUM(C15:N15) -> 1020 | P15: ='1 Produkt- und Absatzplanung '!P33 -> 408 | Q15: ='1 Produkt- und Absatzplanung '!Q33 -> 612 | R15: ='1 Produkt- und Absatzplanung '!R33 -> 1122 | S15: ='1 Produkt- und Absatzplanung '!S33 -> 1479 | T15: =SUM(P15:S15) -> 3621 | U15: ='1 Produkt- und Absatzplanung '!U33 -> 4029 | V15: ='1 Produkt- und Absatzplanung '!V33 -> 4437 | W15: ='1 Produkt- und Absatzplanung '!W33 -> 5202 | X15: ='1 Produkt- und Absatzplanung '!X33 -> 5814 | Y15: =SUM(U15:X15) -> 19482 | Z15: ='1 Produkt- und Absatzplanung '!Z33 -> 19686 | AA15: ='1 Produkt- und Absatzplanung '!AA33 -> 19890 | AB15: ='1 Produkt- und Absatzplanung '!AB33 -> 20808 | AC15: ='1 Produkt- und Absatzplanung '!AC33 -> 21318 | AD15: =SUM(Z15:AC15) -> 81702
B16: Abschreibungen und Amortisationen | C16: =SUM(C17:C18) -> 138.88889 | D16: =SUM(D17:D18) -> 138.88889 | E16: =SUM(E17:E18) -> 1650.1889 | F16: =SUM(F17:F18) -> 1650.1889 | G16: =SUM(G17:G18) -> 1650.1889 | H16: =SUM(H17:H18) -> 1650.1889 | I16: =SUM(I17:I18) -> 1650.1889 | J16: =SUM(J17:J18) -> 1650.1889 | ... N16: =SUM(N17:N18) -> 1650.1889 | O16: =SUM(C16:N16) -> 16779.667 | P16: =SUM(P17:P18) -> 7286.6667 | Q16: =SUM(Q17:Q18) -> 8909.5833 | R16: =SUM(R17:R18) -> 12987.5 | S16: =SUM(S17:S18) -> 15837.917 | T16: =SUM(P16:S16) -> 45021.667 | U16: =SUM(U17:U18) -> 18816.667 | V16: =SUM(V17:V18) -> 21908.333 | W16: =SUM(W17:W18) -> 27850.417 | X16: =SUM(X17:X18) -> 32565 | Y16: =SUM(U16:X16) -> 101140.42 | Z16: =SUM(Z17:Z18) -> 32104.583 | AA16: =SUM(AA17:AA18) -> 33881.667 | AB16: =SUM(AB17:AB18) -> 41051.25 | AC16: =SUM(AC17:AC18) -> 44820.833 | AD16: =SUM(Z16:AC16) -> 151858.33
B17: Abschreibung Hardware | C17: ='2 Investit- und Personalplanung'!$C$19/36 -> 138.88889 | D17: ='2 Investit- und Personalplanung'!$C$19/36 -> 138.88889 | E17: =('2 Investit- und Personalplanung'!$C$19/36)+678 -> 816.88889 | F17: =('2 Investit- und Personalplanung'!$C$19/36)+678 -> 816.88889 | G17: =('2 Investit- und Personalplanung'!$C$19/36)+678 -> 816.88889 | H17: =('2 Investit- und Personalplanung'!$C$19/36)+678 -> 816.88889 | I17: =('2 Investit- und Personalplanung'!$C$19/36)+678 -> 816.88889 | J17: =('2 Investit- und Personalplanung'!$C$19/36)+678 -> 816.88889 | K17: =('2 Investit- und Personalplanung'!$C$19/36)+678 -> 816.88889 | L17: =('2 Investit- und Personalplanung'!$C$19/36)+678 -> 816.88889 | ... N17: =('2 Investit- und Personalplanung'!$C$19/36)+678 -> 816.88889 | O17: =SUM('3 GuV - Cashflow'!C17:N17) -> 8446.6667 | P17: =(('2 Investit- und Personalplanung'!$C$19/36*3)+($E$43/36)*3)+($P$43/36*3) -> 5203.3333 | Q17: =(('2 Investit- und Personalplanung'!$C$19/36*3)+($E$43/36)*3)+($P$43/36*3)+($Q$43/36*3) -> 6826.25 | R17: =(('2 Investit- und Personalplanung'!$C$19/36*3)+($E$43/36)*3)+($P$43/36*3)+($Q$43/36*3)+($R$43/36*3) -> 10904.167 | S17: =(('2 Investit- und Personalplanung'!$C$19/36*3)+($E$43/36)*3)+($P$43/36*3)+($Q$43/36*3)+($R$43/36*3)+($S$43/36*3) -> 13754.583 | T17: =SUM(P17:S17) -> 36688.333 | U17: =(('2 Investit- und Personalplanung'!$C$19/36*3)+($E$43/36)*3)+($P$43/36*3)+($Q$43/36*3)+($R$43/36*3)+($S$43/36*3)+($U$43/36*3) -> 16733.333 | V17: =(('2 Investit- und Personalplanung'!$C$19/36*3)+($E$43/36)*3)+($P$43/36*3)+($Q$43/36*3)+($R$43/36*3)+($S$43/36*3)+($U$43/36*3)+($V$43/36*3) -> 19825 | W17: =(('2 Investit- und Personalplanung'!$C$19/36*3)+($E$43/36)*3)+($P$43/36*3)+($Q$43/36*3)+($R$43/36*3)+($S$43/36*3)+($U$43/36*3)+($V$43/36*3)+($W$43/36*3) -> 25767.083 | X17: =(('2 Investit- und Personalplanung'!$C$19/36*3)+($E$43/36)*3)+($P$43/36*3)+($Q$43/36*3)+($R$43/36*3)+($S$43/36*3)+($U$43/36*3)+($V$43/36*3)+($W$43/36*3)+($X$43/36*3) -> 30481.667 | Y17: =SUM(U17:X17) -> 92807.083 | Z17: =(('2 Investit- und Personalplanung'!$C$19/36*3)+($E$43/36)*3)+($P$43/36*3)+($Q$43/36*3)+($R$43/36*3)+($S$43/36*3)+($U$43/36*3)+($V$43/36*3)+($W$43/36*3)+($X$43/36*3)+($Z$43/36*3) -> 32104.583 | AA17: =(('2 Investit- und Personalplanung'!$C$19/36*3)+($E$43/36)*3)+($P$43/36*3)+($Q$43/36*3)+($R$43/36*3)+($S$43/36*3)+($U$43/36*3)+($V$43/36*3)+($W$43/36*3)+($X$43/36*3)+($Z$43/36*3)+($AA$43/36*3) -> 33881.667 | AB17: =(('2 Investit- und Personalplanung'!$C$19/36*3)+($E$43/36)*3)+($P$43/36*3)+($Q$43/36*3)+($R$43/36*3)+($S$43/36*3)+($U$43/36*3)+($V$43/36*3)+($W$43/36*3)+($X$43/36*3)+($Z$43/36*3)+($AA$43/36*3)+($AB$43/36*3) -> 41051.25 | AC17: =(('2 Investit- und Personalplanung'!$C$19/36*3)+($E$43/36)*3)+($P$43/36*3)+($Q$43/36*3)+($R$43/36*3)+($S$43/36*3)+($U$43/36*3)+($V$43/36*3)+($W$43/36*3)+($X$43/36*3)+($Z$43/36*3)+($AA$43/36*3)+($AB$43/36*3)+($AC$43/36*3) -> 44820.833 | AD17: =SUM(Z17:AC17) -> 151858.33
B18: Amortisation App | C18: 0 | D18: 0 | E18: =833.3 -> 833.3 | F18: =833.3 -> 833.3 | G18: =833.3 -> 833.3 | H18: =833.3 -> 833.3 | I18: =833.3 -> 833.3 | J18: =833.3 -> 833.3 | K18: =833.3 -> 833.3 | L18: =833.3 -> 833.3 | ... N18: =833.3 -> 833.3 | O18: =SUM('3 GuV - Cashflow'!C18:N18) -> 8333 | P18: =('2 Investit- und Personalplanung'!$C$18/36)*3 -> 2083.3333 | Q18: =('2 Investit- und Personalplanung'!$C$18/36)*3 -> 2083.3333 | R18: =('2 Investit- und Personalplanung'!$C$18/36)*3 -> 2083.3333 | S18: =('2 Investit- und Personalplanung'!$C$18/36)*3 -> 2083.3333 | T18: =SUM(P18:S18) -> 8333.3333 | U18: =('2 Investit- und Personalplanung'!$C$18/36)*3 -> 2083.3333 | V18: =('2 Investit- und Personalplanung'!$C$18/36)*3 -> 2083.3333 | W18: =('2 Investit- und Personalplanung'!$C$18/36)*3 -> 2083.3333 | X18: =('2 Investit- und Personalplanung'!$C$18/36)*3 -> 2083.3333 | Y18: =SUM(U18:X18) -> 8333.3333 | Z18: 0 | AA18: 0 | AB18: 0 | AC18: 0 | AD18: =SUM(Z18:AC18) -> 0
B19: Sonstige betriebliche Aufwendungen | C19: ='2 Investit- und Personalplanung'!$C$39 -> 150 | D19: ='2 Investit- und Personalplanung'!$C$39 -> 150 | E19: ='2 Investit- und Personalplanung'!$C$39 -> 150 | F19: ='2 Investit- und Personalplanung'!$C$39 -> 150 | G19: ='2 Investit- und Personalplanung'!$C$39 -> 150 | H19: ='2 Investit- und Personalplanung'!$C$39 -> 150 | I19: ='2 Investit- und Personalplanung'!$C$39 -> 150 | J19: ='2 Investit- und Personalplanung'!$C$39 -> 150 | ... N19: ='2 Investit- und Personalplanung'!$C$39 -> 150 | O19: =SUM(C19:N19) -> 1800 | P19: ='2 Investit- und Personalplanung'!$C$39*3 -> 450 | Q19: ='2 Investit- und Personalplanung'!$C$39*3 -> 450 | R19: ='2 Investit- und Personalplanung'!$C$39*3 -> 450 | S19: ='2 Investit- und Personalplanung'!$C$39*3 -> 450 | T19: =SUM(P19:S19) -> 1800 | U19: ='2 Investit- und Personalplanung'!$C$39*3 -> 450 | V19: ='2 Investit- und Personalplanung'!$C$39*3 -> 450 | W19: ='2 Investit- und Personalplanung'!$C$39*3 -> 450 | X19: ='2 Investit- und Personalplanung'!$C$39*3 -> 450 | Y19: =SUM(U19:X19) -> 1800 | Z19: ='2 Investit- und Personalplanung'!$C$39*3 -> 450 | AA19: ='2 Investit- und Personalplanung'!$C$39*3 -> 450 | AB19: ='2 Investit- und Personalplanung'!$C$39*3 -> 450 | AC19: ='2 Investit- und Personalplanung'!$C$39*3 -> 450 | AD19: =SUM(Z19:AC19) -> 1800
B20: Gewährleistungsrückstellung | C20: 0 | D20: 0 | E20: =E43*0.1 -> 2034 | F20: 0 | G20: 0 | H20: 0 | I20: 0 | J20: 0 | K20: 0 | L20: 0 | M20: 0 | N20: 0 | O20: =SUM(C20:N20) -> 2034 | P20: =(P43*0.1) -> 3710 | Q20: =(Q43*0.1) -> 1947.5 | R20: =(R43*0.1) -> 4893.5 | S20: =(S43*0.1) -> 3420.5 | T20: =SUM(P20:S20) -> 13971.5 | U20: =(U43*0.1) -> 3574.5 | V20: =(V43*0.1) -> 3710 | W20: =(W43*0.1) -> 7130.5 | X20: =(X43*0.1) -> 5657.5 | Y20: =SUM(U20:X20) -> 20072.5 | Z20: =(Z43*0.1) -> 1947.5 | AA20: =(AA43*0.1) -> 2132.5 | AB20: =(AB43*0.1) -> 8603.5 | AC20: =(AC43*0.1) -> 4523.5 | AD20: =SUM(Z20:AC20) -> 17207
B21: Weitere Position | O21: =SUM(C21:N21) -> 0 | T21: =SUM(P21:S21) -> 0 | Y21: =SUM(U21:X21) -> 0 | AD21: =SUM(Z21:AC21) -> 0
B22: Weitere Position | O22: =SUM(C22:N22) -> 0 | T22: =SUM(P22:S22) -> 0 | Y22: =SUM(U22:X22) -> 0 | AD22: =SUM(Z22:AC22) -> 0
B23: Summe Aufwendungen | C23: =SUM(C14:C22) -> 277.77778 | D23: =SUM(D14:D22) -> 277.77778 | E23: =SUM(E14:E22) -> 5436.3778 | F23: =SUM(F14:F22) -> 3402.3778 | G23: =SUM(G14:G22) -> 3402.3778 | H23: =SUM(H14:H22) -> 3402.3778 | I23: =SUM(I14:I22) -> 3402.3778 | J23: =SUM(J14:J22) -> 3402.3778 | ... AD23: =SUM(AD14:AD22) -> 642360.07
B25: Operativer Gewinn (EBIT) | C25: =C11-C23 -> -277.77778 | D25: =D11-D23 -> -277.77778 | E25: =E11-E23 -> -5436.3778 | F25: =F11-F23 -> -3402.3778 | G25: =G11-G23 -> -3402.3778 | H25: =H11-H23 -> -3402.3778 | I25: =I11-I23 -> -3402.3778 | J25: =J11-J23 -> -3402.3778 | ... AD25: =AD11-AD23 -> 108427.93
B27: Zinserträge | O27: =SUM(C27:N27) -> 0 | T27: =SUM(P27:S27) -> 0 | Y27: =SUM(U27:X27) -> 0 | AD27: =SUM(Z27:AC27) -> 0
B28: Zinsaufwendungen | O28: =SUM(C28:N28) -> 0 | T28: =SUM(P28:S28) -> 0 | Y28: =SUM(U28:X28) -> 0 | AD28: =SUM(Z28:AC28) -> 0
B29: Steuern | O29: =SUM(C29:N29) -> 0 | T29: =SUM(P29:S29) -> 0 | Y29: =SUM(U29:X29) -> 0 | AD29: =SUM(Z29:AC29) -> 0
B30: Weitere Position | O30: =SUM(C30:N30) -> 0 | T30: =SUM(P30:S30) -> 0 | Y30: =SUM(U30:X30) -> 0 | AD30: =SUM(Z30:AC30) -> 0
B31: Weitere Position | O31: =SUM(C31:N31) -> 0 | T31: =SUM(P31:S31) -> 0 | Y31: =SUM(U31:X31) -> 0 | AD31: =SUM(Z31:AC31) -> 0
B32: Jahresüberschuss | C32: =C25+C27-C28-C29 -> -277.77778 | D32: =D25+D27-D28-D29 -> -277.77778 | E32: =E25+E27-E28-E29 -> -5436.3778 | F32: =F25+F27-F28-F29 -> -3402.3778 | G32: =G25+G27-G28-G29 -> -3402.3778 | H32: =H25+H27-H28-H29 -> -3402.3778 | I32: =I25+I27-I28-I29 -> -3402.3778 | J32: =J25+J27-J28-J29 -> -3402.3778 | ... AD32: =AD25+AD27-AD28-AD29 -> 108427.93
B33: Einstellung in Rücklagen
B34: Gewinn/Verlust nach Rücklagen | C34: =C32-C33 -> -277.77778 | D34: =D32-D33 -> -277.77778 | E34: =E32-E33 -> -5436.3778 | F34: =F32-F33 -> -3402.3778 | G34: =G32-G33 -> -3402.3778 | H34: =H32-H33 -> -3402.3778 | I34: =I32-I33 -> -3402.3778 | J34: =J32-J33 -> -3402.3778 | ... AD34: =AD32-AD33 -> 108427.93
B37: Geplanter Cashflow
C39: Jan J1 | D39: Feb J1 | E39: Mär J1 | F39: Apr J1 | G39: Mai J1 | H39: Jun J1 | I39: Jul J1 | J39: Aug J1 | K39: Sep J1 | L39: Okt J1 | M39: Nov J1 | N39: Dez J1 | O39: Jahr 1 | P39: Q1 J2 | Q39: Q2 J2 | R39: Q3 J2 | S39: Q4 J2 | T39: Jahr 2 | U39: Q1 J3 | V39: Q2 J3 | W39: Q3 J3 | X39: Q4 J3 | Y39: Jahr 3 | Z39: Q1 J4 | AA39: Q2 J4 | AB39: Q3 J4 | AC39: Q4 J4 | AD39: Jahr 4
B40: Jahresüberschuss | C40: =C32 -> -277.77778 | D40: =D32 -> -277.77778 | E40: =E32 -> -5436.3778 | F40: =F32 -> -3402.3778 | G40: =G32 -> -3402.3778 | H40: =H32 -> -3402.3778 | I40: =I32 -> -3402.3778 | J40: =J32 -> -3402.3778 | ... N40: =N32 -> -3402.3778 | O40: =SUM(C40:N40) -> -36613.333 | P40: =P32 -> -6699.3333 | Q40: =Q32 -> -28910.667 | R40: =R32 -> -492.5 | S40: =S32 -> -20974.333 | T40: =SUM(P40:S40) -> -57076.833 | U40: =U32 -> -24546.833 | V40: =V32 -> -26931.667 | W40: =W32 -> 4543.6667 | X40: =X32 -> -18306.5 | Y40: =SUM(U40:X40) -> -65241.333 | Z40: =Z32 -> 7717.7333 | AA40: =AA32 -> 7560.5667 | AB40: =AB32 -> 72304.4 | AC40: =AC32 -> 20845.233 | AD40: =SUM(Z40:AC40) -> 108427.93
B41: + Abschreibungen | C41: =C16 -> 138.88889 | D41: =D16 -> 138.88889 | E41: =E16 -> 1650.1889 | F41: =F16 -> 1650.1889 | G41: =G16 -> 1650.1889 | H41: =H16 -> 1650.1889 | I41: =I16 -> 1650.1889 | J41: =J16 -> 1650.1889 | ... N41: =N16 -> 1650.1889 | O41: =SUM(C41:N41) -> 16779.667 | P41: =P16 -> 7286.6667 | Q41: =Q16 -> 8909.5833 | R41: =R16 -> 12987.5 | S41: =S16 -> 15837.917 | T41: =SUM(P41:S41) -> 45021.667 | U41: =U16 -> 18816.667 | V41: =V16 -> 21908.333 | W41: =W16 -> 27850.417 | X41: =X16 -> 32565 | Y41: =SUM(U41:X41) -> 101140.42 | Z41: =Z16 -> 32104.583 | AA41: =AA16 -> 33881.667 | AB41: =AB16 -> 41051.25 | AC41: =AC16 -> 44820.833 | AD41: =SUM(Z41:AC41) -> 151858.33
B42: + Zuführung zu Rückstellungen | C42: =C20 -> 0 | D42: =D20 -> 0 | E42: =E20 -> 2034 | F42: =F20 -> 0 | G42: =G20 -> 0 | H42: =H20 -> 0 | I42: =I20 -> 0 | J42: =J20 -> 0 | ... N42: =N20 -> 0 | O42: =SUM(C42:N42) -> 2034 | P42: =P20 -> 3710 | Q42: =Q20 -> 1947.5 | R42: =R20 -> 4893.5 | S42: =S20 -> 3420.5 | T42: =SUM(P42:S42) -> 13971.5 | U42: =U20 -> 3574.5 | V42: =V20 -> 3710 | W42: =W20 -> 7130.5 | X42: =X20 -> 5657.5 | Y42: =SUM(U42:X42) -> 20072.5 | Z42: =Z20 -> 1947.5 | AA42: =AA20 -> 2132.5 | AB42: =AB20 -> 8603.5 | AC42: =AC20 -> 4523.5 | AD42: =SUM(Z42:AC42) -> 17207
B43: - Investitionen | C43: =('1 Produkt- und Absatzplanung '!$D$37*'1 Produkt- und Absatzplanung '!C9)+('1 Produkt- und Absatzplanung '!$D$38*'1 Produkt- und Absatzplanung '!C15)+('1 Produkt- und Absatzplanung '!$D$39*'1 Produkt- und Absatzplanung '!C21) -> 0 | D43: =('1 Produkt- und Absatzplanung '!$D$37*'1 Produkt- und Absatzplanung '!D9)+('1 Produkt- und Absatzplanung '!$D$38*'1 Produkt- und Absatzplanung '!D15)+('1 Produkt- und Absatzplanung '!$D$39*'1 Produkt- und Absatzplanung '!D21) -> 0 | E43: =('1 Produkt- und Absatzplanung '!$D$37*'1 Produkt- und Absatzplanung '!E9)+('1 Produkt- und Absatzplanung '!$D$38*'1 Produkt- und Absatzplanung '!E15)+('1 Produkt- und Absatzplanung '!$D$39*'1 Produkt- und Absatzplanung '!E21) -> 20340 | F43: =('1 Produkt- und Absatzplanung '!$D$37*'1 Produkt- und Absatzplanung '!F9)+('1 Produkt- und Absatzplanung '!$D$38*'1 Produkt- und Absatzplanung '!F15)+('1 Produkt- und Absatzplanung '!$D$39*'1 Produkt- und Absatzplanung '!F21) -> 0 | G43: =('1 Produkt- und Absatzplanung '!$D$37*'1 Produkt- und Absatzplanung '!G9)+('1 Produkt- und Absatzplanung '!$D$38*'1 Produkt- und Absatzplanung '!G15)+('1 Produkt- und Absatzplanung '!$D$39*'1 Produkt- und Absatzplanung '!G21) -> 0 | H43: =('1 Produkt- und Absatzplanung '!$D$37*'1 Produkt- und Absatzplanung '!H9)+('1 Produkt- und Absatzplanung '!$D$38*'1 Produkt- und Absatzplanung '!H15)+('1 Produkt- und Absatzplanung '!$D$39*'1 Produkt- und Absatzplanung '!H21) -> 0 | I43: =('1 Produkt- und Absatzplanung '!$D$37*'1 Produkt- und Absatzplanung '!I9)+('1 Produkt- und Absatzplanung '!$D$38*'1 Produkt- und Absatzplanung '!I15)+('1 Produkt- und Absatzplanung '!$D$39*'1 Produkt- und Absatzplanung '!I21) -> 0 | J43: =('1 Produkt- und Absatzplanung '!$D$37*'1 Produkt- und Absatzplanung '!J9)+('1 Produkt- und Absatzplanung '!$D$38*'1 Produkt- und Absatzplanung '!J15)+('1 Produkt- und Absatzplanung '!$D$39*'1 Produkt- und Absatzplanung '!J21) -> 0 | ... N43: =('1 Produkt- und Absatzplanung '!$D$37*'1 Produkt- und Absatzplanung '!N9)+('1 Produkt- und Absatzplanung '!$D$38*'1 Produkt- und Absatzplanung '!N15)+('1 Produkt- und Absatzplanung '!$D$39*'1 Produkt- und Absatzplanung '!N21) -> 0 | O43: =SUM(C43:N43) -> 20340 | P43: =('1 Produkt- und Absatzplanung '!$D$37*'1 Produkt- und Absatzplanung '!P9)+('1 Produkt- und Absatzplanung '!$D$38*'1 Produkt- und Absatzplanung '!P15)+('1 Produkt- und Absatzplanung '!$D$39*'1 Produkt- und Absatzplanung '!P21) -> 37100 | Q43: =('1 Produkt- und Absatzplanung '!$D$37*'1 Produkt- und Absatzplanung '!Q9)+('1 Produkt- und Absatzplanung '!$D$38*'1 Produkt- und Absatzplanung '!Q15)+('1 Produkt- und Absatzplanung '!$D$39*'1 Produkt- und Absatzplanung '!Q21) -> 19475 | R43: =('1 Produkt- und Absatzplanung '!$D$37*'1 Produkt- und Absatzplanung '!R9)+('1 Produkt- und Absatzplanung '!$D$38*'1 Produkt- und Absatzplanung '!R15)+('1 Produkt- und Absatzplanung '!$D$39*'1 Produkt- und Absatzplanung '!R21) -> 48935 | S43: =('1 Produkt- und Absatzplanung '!$D$37*'1 Produkt- und Absatzplanung '!S9)+('1 Produkt- und Absatzplanung '!$D$38*'1 Produkt- und Absatzplanung '!S15)+('1 Produkt- und Absatzplanung '!$D$39*'1 Produkt- und Absatzplanung '!S21) -> 34205 | T43: =SUM(P43:S43) -> 139715 | U43: =('1 Produkt- und Absatzplanung '!$D$37*'1 Produkt- und Absatzplanung '!U9)+('1 Produkt- und Absatzplanung '!$D$38*'1 Produkt- und Absatzplanung '!U15)+('1 Produkt- und Absatzplanung '!$D$39*'1 Produkt- und Absatzplanung '!U21) -> 35745 | V43: =('1 Produkt- und Absatzplanung '!$D$37*'1 Produkt- und Absatzplanung '!V9)+('1 Produkt- und Absatzplanung '!$D$38*'1 Produkt- und Absatzplanung '!V15)+('1 Produkt- und Absatzplanung '!$D$39*'1 Produkt- und Absatzplanung '!V21) -> 37100 | W43: =('1 Produkt- und Absatzplanung '!$D$37*'1 Produkt- und Absatzplanung '!W9)+('1 Produkt- und Absatzplanung '!$D$38*'1 Produkt- und Absatzplanung '!W15)+('1 Produkt- und Absatzplanung '!$D$39*'1 Produkt- und Absatzplanung '!W21) -> 71305 | X43: =('1 Produkt- und Absatzplanung '!$D$37*'1 Produkt- und Absatzplanung '!X9)+('1 Produkt- und Absatzplanung '!$D$38*'1 Produkt- und Absatzplanung '!X15)+('1 Produkt- und Absatzplanung '!$D$39*'1 Produkt- und Absatzplanung '!X21) -> 56575 | Y43: =SUM(U43:X43) -> 200725 | Z43: =('1 Produkt- und Absatzplanung '!$D$37*'1 Produkt- und Absatzplanung '!Z9)+('1 Produkt- und Absatzplanung '!$D$38*'1 Produkt- und Absatzplanung '!Z15)+('1 Produkt- und Absatzplanung '!$D$39*'1 Produkt- und Absatzplanung '!Z21) -> 19475 | AA43: =('1 Produkt- und Absatzplanung '!$D$37*'1 Produkt- und Absatzplanung '!AA9)+('1 Produkt- und Absatzplanung '!$D$38*'1 Produkt- und Absatzplanung '!AA15)+('1 Produkt- und Absatzplanung '!$D$39*'1 Produkt- und Absatzplanung '!AA21) -> 21325 | AB43: =('1 Produkt- und Absatzplanung '!$D$37*'1 Produkt- und Absatzplanung '!AB9)+('1 Produkt- und Absatzplanung '!$D$38*'1 Produkt- und Absatzplanung '!AB15)+('1 Produkt- und Absatzplanung '!$D$39*'1 Produkt- und Absatzplanung '!AB21) -> 86035 | AC43: =('1 Produkt- und Absatzplanung '!$D$37*'1 Produkt- und Absatzplanung '!AC9)+('1 Produkt- und Absatzplanung '!$D$38*'1 Produkt- und Absatzplanung '!AC15)+('1 Produkt- und Absatzplanung '!$D$39*'1 Produkt- und Absatzplanung '!AC21) -> 45235 | AD43: =SUM(Z43:AC43) -> 172070
B44: = Cashflow | O44: =O40+O41+O42-O43 -> -38139.667 | P44: =SUM(P40:P43) -> 41397.333 | Q44: =SUM(Q40:Q43) -> 1421.4167 | R44: =SUM(R40:R43) -> 66323.5 | S44: =SUM(S40:S43) -> 32489.083 | T44: =T40+T41+T42-T43 -> -137798.67 | U44: =SUM(U40:U43) -> 33589.333 | V44: =SUM(V40:V43) -> 35786.667 | W44: =SUM(W40:W43) -> 110829.58 | X44: =SUM(X40:X43) -> 76491 | Y44: =Y40+Y41+Y42-Y43 -> -144753.42 | Z44: =SUM(Z40:Z43) -> 61244.817 | AA44: =SUM(AA40:AA43) -> 64899.733 | AB44: =SUM(AB40:AB43) -> 207994.15 | AC44: =SUM(AC40:AC43) -> 115424.57 | AD44: =AD40+AD41+AD42-AD43 -> 105423.27
C47: Rst Quelle | AF47: Tunguz (2015) "Winning with Data" — B2B-SaaS mit dediziertem Onboarding zeigt typischerweise 10–15% jährlichen Churn. Da BetterSquad Hardware-Lock-in hat (Daten im System, Geräte vor Ort), ist 10% konservativ realistisch und für Investoren glaubwürdig.
C48: https://www.haufe.de/id/kommentar/gewaehrleistungsrueckstellung-darf-den-pauschalsatz-von-05-uebersteigen-HI1202489.html
AF49: Reichheld & Schefter (2000, HBR) — B2B-SaaS zeigt nach erstem Vertragszyklus 70–80% Renewal Rate. 30% Churn am oberen Rand ist realistisch für Hardware-SaaS weil:
AF51: Budgetdruck bei Amateurvereinen nach 2 Jahren
...

Sheet 4 Breakeven
B2: 4 - Breakeven
B3: Breakeven-Analyse
B33: Planungszeitraum | C33: Jahr 1 | D33: Jahr 2 | E33: Jahr 3 | F33: Jahr 4
B34: Umsatz | C34: ='3 GuV - Cashflow'!O6 -> 0 | D34: ='3 GuV - Cashflow'!T6 -> 197559 | E34: ='3 GuV - Cashflow'!Y6 -> 377318 | F34: ='3 GuV - Cashflow'!AD6 -> 750788
B35: EBITDA | C35: =C34-'3 GuV - Cashflow'!T14-'3 GuV - Cashflow'!T15 -> -148821 | D35: =D34-'3 GuV - Cashflow'!T14-'3 GuV - Cashflow'!T15 -> 48738 | E35: =E34-'3 GuV - Cashflow'!Y14-'3 GuV - Cashflow'!Y15 -> 158912 | F35: =F34-'3 GuV - Cashflow'!AD14-'3 GuV - Cashflow'!AD15 -> 431151.6
B37: EBITDA = Gewinn vor Zinsen, Steuern, Abschreibungen auf Sachanlagen und Abschreibungen auf immaterielle Vermögensgegenstände

Sheet 5 Liquiditätsplanung
B2: 5 - Liquiditätsplanung
D4: Jan J1 | E4: Feb J1 | F4: Mär J1 | G4: Apr J1 | H4: Mai J1 | I4: Jun J1 | J4: Jul J1 | K4: Aug J1 | L4: Sep J1 | M4: Okt J1 | N4: Nov J1 | O4: Dez J1 | P4: Jahr 1 | Q4: Q1 J2 | R4: Q2 J2 | S4: Q3 J2 | T4: Q4 J2 | U4: Jahr 2 | V4: Q1 J3 | W4: Q2 J3 | X4: Q3 J3 | Y4: Q4 J3 | Z4: Jahr 3 | AA4: Q1 J4 | AB4: Q2 J4 | AC4: Q3 J4 | AD4: Q4 J4 | AE4: Jahr 4
B5: Einzahlungen | D5: =SUM(D6:D7) -> 100000 | E5: =SUM(E6:E7) -> 0 | F5: =SUM(F6:F7) -> 0 | G5: =SUM(G6:G7) -> 0 | H5: =SUM(H6:H7) -> 0 | I5: =SUM(I6:I7) -> 30000 | J5: =SUM(J6:J7) -> 0 | K5: =SUM(K6:K7) -> 0 | ... AE5: =SUM(AE6:AE7) -> 750788
B6: Umsatz | D6: ='3 GuV - Cashflow'!C6 -> 0 | E6: ='3 GuV - Cashflow'!D6 -> 0 | F6: ='3 GuV - Cashflow'!E6 -> 0 | G6: ='3 GuV - Cashflow'!F6 -> 0 | H6: ='3 GuV - Cashflow'!G6 -> 0 | I6: ='3 GuV - Cashflow'!H6 -> 0 | J6: ='3 GuV - Cashflow'!I6 -> 0 | K6: ='3 GuV - Cashflow'!J6 -> 0 | ... O6: ='3 GuV - Cashflow'!N6 -> 0 | P6: =SUM(D6:O6) -> 0 | Q6: ='3 GuV - Cashflow'!P6 -> 48742 | R6: ='3 GuV - Cashflow'!Q6 -> 28218 | S6: ='3 GuV - Cashflow'!R6 -> 68248 | T6: ='3 GuV - Cashflow'!S6 -> 52351 | U6: =SUM(Q6:T6) -> 197559 | V6: ='3 GuV - Cashflow'!U6 -> 70871 | W6: ='3 GuV - Cashflow'!V6 -> 75213 | X6: ='3 GuV - Cashflow'!W6 -> 122758 | Y6: ='3 GuV - Cashflow'!X6 -> 108476 | Z6: =SUM(V6:Y6) -> 377318 | AA6: ='3 GuV - Cashflow'!Z6 -> 153494 | AB6: ='3 GuV - Cashflow'!AA6 -> 157280 | AC6: ='3 GuV - Cashflow'!AB6 -> 243752 | AD6: ='3 GuV - Cashflow'!AC6 -> 196262 | AE6: =SUM(AA6:AD6) -> 750788
B7: Finanzierung | D7: ='6 Kapitalbedarfsplanung'!D5 -> 100000 | I7: 30000 | P7: =SUM(D7:O7) -> 130000 | S7: 100000 | U7: =SUM(Q7:T7) -> 100000 | Z7: =SUM(V7:Y7) -> 0 | AE7: =SUM(AA7:AD7) -> 0
B8: Auszahlungen | D8: =SUM(D9:D14) -> 32273 | E8: =SUM(E9:E14) -> 150 | F8: =SUM(F9:F14) -> 20592 | G8: =SUM(G9:G14) -> 252 | H8: =SUM(H9:H14) -> 252 | I8: =SUM(I9:I14) -> 252 | J8: =SUM(J9:J14) -> 252 | K8: =SUM(K9:K14) -> 252 | ... AE8: =SUM(AE9:AE14) -> 520822.03
B9: Wareneinkauf | P9: =SUM(D9:O9) -> 0 | U9: =SUM(Q9:T9) -> 0 | Z9: =SUM(V9:Y9) -> 0 | AE9: =SUM(AA9:AD9) -> 0
B10: Personal | D10: ='2 Investit- und Personalplanung'!$H$14/12 -> 0 | E10: ='2 Investit- und Personalplanung'!$H$14/12 -> 0 | F10: ='2 Investit- und Personalplanung'!$H$14/12 -> 0 | G10: ='2 Investit- und Personalplanung'!$H$14/12 -> 0 | H10: ='2 Investit- und Personalplanung'!$H$14/12 -> 0 | I10: ='2 Investit- und Personalplanung'!$H$14/12 -> 0 | J10: ='2 Investit- und Personalplanung'!$H$14/12 -> 0 | K10: ='2 Investit- und Personalplanung'!$H$14/12 -> 0 | ... O10: ='2 Investit- und Personalplanung'!$H$14/12 -> 0 | P10: =SUM(D10:O10) -> 0 | Q10: ='2 Investit- und Personalplanung'!$J$39/4 -> 36300 | R10: ='2 Investit- und Personalplanung'!$J$39/4 -> 36300 | S10: ='2 Investit- und Personalplanung'!$J$39/4 -> 36300 | T10: ='2 Investit- und Personalplanung'!$J$39/4 -> 36300 | U10: =SUM(Q10:T10) -> 145200 | V10: ='2 Investit- und Personalplanung'!$L$39/4 -> 49731 | W10: ='2 Investit- und Personalplanung'!$L$39/4 -> 49731 | X10: ='2 Investit- und Personalplanung'!$L$39/4 -> 49731 | Y10: ='2 Investit- und Personalplanung'!$L$39/4 -> 49731 | Z10: =SUM(V10:Y10) -> 198924 | AA10: ='2 Investit- und Personalplanung'!$N$39/4 -> 59483.6 | AB10: ='2 Investit- und Personalplanung'!$N$39/4 -> 59483.6 | AC10: ='2 Investit- und Personalplanung'!$N$39/4 -> 59483.6 | AD10: ='2 Investit- und Personalplanung'!$N$39/4 -> 59483.6 | AE10: =SUM(AA10:AD10) -> 237934.4
B11: Betrieb und Verwaltung | D11: ='2 Investit- und Personalplanung'!$C$39+'3 GuV - Cashflow'!C15 -> 150 | E11: ='2 Investit- und Personalplanung'!$C$39+'3 GuV - Cashflow'!D15 -> 150 | F11: ='2 Investit- und Personalplanung'!$C$39+'3 GuV - Cashflow'!E15 -> 252 | G11: ='2 Investit- und Personalplanung'!$C$39+'3 GuV - Cashflow'!F15 -> 252 | H11: ='2 Investit- und Personalplanung'!$C$39+'3 GuV - Cashflow'!G15 -> 252 | I11: ='2 Investit- und Personalplanung'!$C$39+'3 GuV - Cashflow'!H15 -> 252 | J11: ='2 Investit- und Personalplanung'!$C$39+'3 GuV - Cashflow'!I15 -> 252 | K11: ='2 Investit- und Personalplanung'!$C$39+'3 GuV - Cashflow'!J15 -> 252 | ... O11: ='2 Investit- und Personalplanung'!$C$39+'3 GuV - Cashflow'!N15 -> 252 | P11: =SUM(D11:O11) -> 2820 | Q11: ='2 Investit- und Personalplanung'!$C$39+'3 GuV - Cashflow'!P15 -> 558 | R11: ='2 Investit- und Personalplanung'!$C$39+'3 GuV - Cashflow'!Q15 -> 762 | S11: ='2 Investit- und Personalplanung'!$C$39+'3 GuV - Cashflow'!R15 -> 1272 | T11: ='2 Investit- und Personalplanung'!$C$39+'3 GuV - Cashflow'!S15 -> 1629 | U11: =SUM(Q11:T11) -> 4221 | V11: ='2 Investit- und Personalplanung'!$C$39+'3 GuV - Cashflow'!U15 -> 4179 | W11: ='2 Investit- und Personalplanung'!$C$39+'3 GuV - Cashflow'!V15 -> 4587 | X11: ='2 Investit- und Personalplanung'!$C$39+'3 GuV - Cashflow'!W15 -> 5352 | Y11: ='2 Investit- und Personalplanung'!$C$39+'3 GuV - Cashflow'!X15 -> 5964 | Z11: =SUM(V11:Y11) -> 20082 | AA11: ='2 Investit- und Personalplanung'!$C$39+'3 GuV - Cashflow'!Z15 -> 19836 | AB11: ='2 Investit- und Personalplanung'!$C$39+'3 GuV - Cashflow'!AA15 -> 20040 | AC11: ='2 Investit- und Personalplanung'!$C$39+'3 GuV - Cashflow'!AB15 -> 20958 | AD11: ='2 Investit- und Personalplanung'!$C$39+'3 GuV - Cashflow'!AC15 -> 21468 | AE11: =SUM(AA11:AD11) -> 82302
B12: Investitionen | D12: ='2 Investit- und Personalplanung'!C27 -> 32123 | E12: 0 | F12: ='3 GuV - Cashflow'!E43 -> 20340 | G12: 0 | H12: 0 | I12: 0 | J12: 0 | K12: 0 | L12: 0 | M12: 0 | N12: 0 | O12: 0 | P12: =SUM(D12:O12) -> 52463 | Q12: ='3 GuV - Cashflow'!P43 -> 37100 | R12: ='3 GuV - Cashflow'!Q43 -> 19475 | S12: ='3 GuV - Cashflow'!R43 -> 48935 | T12: ='3 GuV - Cashflow'!S43 -> 34205 | U12: =SUM(Q12:T12) -> 139715 | V12: ='3 GuV - Cashflow'!U43 -> 35745 | W12: ='3 GuV - Cashflow'!V43 -> 37100 | X12: ='3 GuV - Cashflow'!W43 -> 71305 | Y12: ='3 GuV - Cashflow'!X43 -> 56575 | Z12: =SUM(V12:Y12) -> 200725 | AA12: ='3 GuV - Cashflow'!Z43 -> 19475 | AB12: ='3 GuV - Cashflow'!AA43 -> 21325 | AC12: ='3 GuV - Cashflow'!AB43 -> 86035 | AD12: ='3 GuV - Cashflow'!AC43 -> 45235 | AE12: =SUM(AA12:AD12) -> 172070
B13: Zins/Tilgung | P13: =SUM(D13:O13) -> 0 | S13: =($S$7*0.045)/4 -> 1125 | T13: =($S$7*0.045)/4 -> 1125 | U13: =SUM(Q13:T13) -> 2250 | V13: =($S$7*0.045)/4 -> 1125 | W13: =($S$7*0.045)/4 -> 1125 | X13: =C22+C24 -> 7375 | Y13: =(S7-C22)*0.045/4+C22 -> 7304.6875 | Z13: =SUM(V13:Y13) -> 16929.688 | AA13: =(S7-C22*2)*0.045/4+C22 -> 7234.375 | AB13: =($S$7-$C$22*3)*0.045/4+$C$22 -> 7164.0625 | AC13: =($S$7-$C$22*4)*0.045/4+$C$22 -> 7093.75 | AD13: =($S$7-$C$22*5)*0.045/4+$C$22 -> 7023.4375 | AE13: =SUM(AA13:AD13) -> 28515.625
B14: Kasse | P14: =SUM(D14:O14) -> 0 | U14: =SUM(Q14:T14) -> 0 | Z14: =SUM(V14:Y14) -> 0 | AE14: =SUM(AA14:AD14) -> 0
B15: Dispo/Kreditlinie | D15: =D5-D8 -> 67727 | E15: =E5-E8 -> -150 | F15: =F5-F8 -> -20592 | G15: =G5-G8 -> -252 | H15: =H5-H8 -> -252 | I15: =I5-I8 -> 29748 | J15: =J5-J8 -> -252 | K15: =K5-K8 -> -252 | ... AE15: =AE5-AE8 -> 229965.97
B16: Liquiditätsreserve | P16: =SUM(D16:O16) -> 0 | U16: =SUM(Q16:T16) -> 0 | Z16: =SUM(V16:Y16) -> 0 | AE16: =SUM(AA16:AD16) -> 0
B20: Tilgungsrate für KFW Kredit:
B21: 4 Jahre / 16 Quartale abbezahlen
C22: =100000/16 -> 6250
B24: Zins für Quartale vor Tilgung | C24: =100000*0.045/4 -> 1125

Sheet 6 Kapitalbedarfsplanung
B2: 6 - Kapitalbedarfsplanung
B4: Finanzierungsquellen | C4: Prozentsatz | D4: Gesamtbeträge | E4: Kreditzins | F4: Laufzeit in Monaten | G4: Monatliche Zahlungen | H4: Anmerkungen
B5: Eigenkapital des Eigentümers | C5: =IF($C$31=0,0,D5/$C$31) -> 0 | D5: 100000
B6: Externe Investoren/Stipendien | C6: =IF($C$31=0,0,D6/$C$31) -> 0 | D6: ='5 Liquiditätsplanung'!I7 -> 30000 | H6: EXIST Sachmittel Förderung
B7: Zusätzliche Kredite oder Schulden
B8: Geschäftskredit | C8: =IF($C$31=0,0,D8/$C$31) -> 0 | D8: 100000 | E8: 0.045 | F8: 48 | G8: =PMT(E8/12,F8,-D8) -> 2280.3486
B9: Gewerbliche Hypothek | C9: =IF($C$31=0,0,D9/$C$31) -> 0 | D9: 0 | G9: =PMT(E9/12,F9,-D9) -> #NUM!
B10: Kreditkartenschulden | C10: =IF($C$31=0,0,D10/$C$31) -> 0 | D10: 0 | G10: =PMT(E10/12,F10,-D10) -> #NUM!
B11: Fahrzeugkredite | C11: =IF($C$31=0,0,D11/$C$31) -> 0 | D11: 0 | G11: =PMT(E11/12,F11,-D11) -> #NUM!
B12: Sonstige Bankschulden | C12: =IF($C$31=0,0,D12/$C$31) -> 0 | D12: 0 | G12: =PMT(E12/12,F12,-D12) -> #NUM!
B13: Gesamte Finanzierungsquellen | C13: =IF($C$31=0,0,D13/$C$31) -> 0 | D13: =SUM(D5:D12) -> 230000 | G13: =SUM(G8:G12) -> #NUM!
B14: =IF($D$13<'2 Investit- und Personalplanung'!$C$27,"Sie benötigen mehr Finanzierung","Sie sind ausreichend finanziert") -> Sie sind ausreichend finanziert
B16: Gesamte Finanzierungsquellen müssen der Startaufwendungen entsprechen

Sheet 7 Bilanz
B2: 7 - Bilanz
B3: Geplante Bilanz
B5: Aktiva
D6: Jan J1 | E6: Feb J1 | F6: Mär J1 | G6: Apr J1 | H6: Mai J1 | I6: Jun J1 | J6: Jul J1 | K6: Aug J1 | L6: Sep J1 | M6: Okt J1 | N6: Nov J1 | O6: Dez J1 | P6: Jahr 1 | Q6: Q1 J2 | R6: Q2 J2 | S6: Q3 J2 | T6: Q4 J2 | U6: Jahr 2 | V6: Q1 J3 | W6: Q2 J3 | X6: Q3 J3 | Y6: Q4 J3 | Z6: Jahr 3 | AA6: Q1 J4 | AB6: Q2 J4 | AC6: Q3 J4 | AD6: Q4 J4 | AE6: Jahr 4
B7: Anlagevermögen
C8: Immaterielles Vermögen (gekaufte Software, Rechte, Lizenzen) | D8: =MAX(0,'2 Investit- und Personalplanung'!C18-SUM('3 GuV - Cashflow'!C18:C18)) -> 25000 | E8: =MAX(0,'2 Investit- und Personalplanung'!C18-SUM('3 GuV - Cashflow'!C18:D18)) -> 25000 | F8: =MAX(0,'2 Investit- und Personalplanung'!C18-SUM('3 GuV - Cashflow'!C18:E18)) -> 24166.7 | G8: =MAX(0,'2 Investit- und Personalplanung'!C18-SUM('3 GuV - Cashflow'!C18:F18)) -> 23333.4 | H8: =MAX(0,'2 Investit- und Personalplanung'!C18-SUM('3 GuV - Cashflow'!C18:G18)) -> 22500.1 | I8: =MAX(0,'2 Investit- und Personalplanung'!C18-SUM('3 GuV - Cashflow'!C18:H18)) -> 21666.8 | J8: =MAX(0,'2 Investit- und Personalplanung'!C18-SUM('3 GuV - Cashflow'!C18:I18)) -> 20833.5 | K8: =MAX(0,'2 Investit- und Personalplanung'!C18-SUM('3 GuV - Cashflow'!C18:J18)) -> 20000.2 | L8: =MAX(0,'2 Investit- und Personalplanung'!C18-SUM('3 GuV - Cashflow'!C18:K18)) -> 19166.9 | M8: =MAX(0,'2 Investit- und Personalplanung'!C18-SUM('3 GuV - Cashflow'!C18:L18)) -> 18333.6 | N8: =MAX(0,'2 Investit- und Personalplanung'!C18-SUM('3 GuV - Cashflow'!C18:M18)) -> 17500.3 | O8: =MAX(0,'2 Investit- und Personalplanung'!C18-SUM('3 GuV - Cashflow'!C18:N18)) -> 16667 | P8: =MAX(0,'2 Investit- und Personalplanung'!C18-SUM('3 GuV - Cashflow'!C18:N18)) -> 16667 | Q8: =MAX(0,'2 Investit- und Personalplanung'!C18-(SUM('3 GuV - Cashflow'!C18:N18)+SUM('3 GuV - Cashflow'!P18:P18))) -> 14583.667 | R8: =MAX(0,'2 Investit- und Personalplanung'!C18-(SUM('3 GuV - Cashflow'!C18:N18)+SUM('3 GuV - Cashflow'!P18:Q18))) -> 12500.333 | S8: =MAX(0,'2 Investit- und Personalplanung'!C18-(SUM('3 GuV - Cashflow'!C18:N18)+SUM('3 GuV - Cashflow'!P18:R18))) -> 10417 | T8: =MAX(0,'2 Investit- und Personalplanung'!C18-(SUM('3 GuV - Cashflow'!C18:N18)+SUM('3 GuV - Cashflow'!P18:S18))) -> 8333.6667 | U8: =MAX(0,'2 Investit- und Personalplanung'!C18-(SUM('3 GuV - Cashflow'!C18:N18)+SUM('3 GuV - Cashflow'!P18:T18))) -> 0.33333333 | V8: =MAX(0,'2 Investit- und Personalplanung'!C18-(SUM('3 GuV - Cashflow'!C18:N18)+SUM('3 GuV - Cashflow'!P18:U18))) -> 0 | W8: =MAX(0,'2 Investit- und Personalplanung'!C18-(SUM('3 GuV - Cashflow'!C18:N18)+SUM('3 GuV - Cashflow'!P18:V18))) -> 0 | X8: =MAX(0,'2 Investit- und Personalplanung'!C18-(SUM('3 GuV - Cashflow'!C18:N18)+SUM('3 GuV - Cashflow'!P18:W18))) -> 0 | Y8: =MAX(0,'2 Investit- und Personalplanung'!C18-(SUM('3 GuV - Cashflow'!C18:N18)+SUM('3 GuV - Cashflow'!P18:X18))) -> 0 | Z8: =MAX(0,'2 Investit- und Personalplanung'!C18-(SUM('3 GuV - Cashflow'!C18:N18)+SUM('3 GuV - Cashflow'!P18:Y18))) -> 0 | AE8: =SUM(AA8:AD8) -> 0
C9: Grundstücke und Gebäude | P9: =SUM(D9:O9) -> 0 | U9: =SUM(Q9:T9) -> 0 | Z9: =SUM(V9:Y9) -> 0 | AE9: =SUM(AA9:AD9) -> 0
